<?xml version="1.0"?>
<robot name="tello">

    <material name="gray"><color rgba="0.5 0.5 0.5 1.0"/></material>
    <material name="white"><color rgba="0.9 0.9 0.9 1.0"/></material>
    <material name="red"><color rgba="1.0 0 0 1.0"/></material>

    <link name="base_link">
        <visual>
            <origin xyz="0 0 0.01"/>
            <geometry><box size="0.07 0.02 0.02"/></geometry>
            <material name="white"/>
        </visual>
        <visual>
            <origin xyz="0 0 -0.01"/>
            <geometry><box size="0.07 0.02 0.02"/></geometry>
            <material name="gray"/>
        </visual>
        <inertial>
            <mass value="0.08"/> <inertia ixx="0.0002" ixy="0" ixz="0" iyy="0.0004" iyz="0" izz="0.0002"/>
        </inertial>
        <collision name="collision">
            <geometry><box size="0.18 0.18 0.05"/></geometry>
        </collision>
    </link>

    <link name="rotor_0">
        <visual>
            <origin xyz="0 0 0"/>
            <geometry><cylinder length="0.01" radius="0.045"/></geometry>
            <material name="gray"/>
        </visual>
        <inertial>
            <mass value="0.005"/>
            <inertia ixx="1e-6" ixy="0" ixz="0" iyy="1e-6" iyz="0" izz="2e-6"/>
        </inertial>
    </link>
    <joint name="rotor_0_joint" type="continuous">
        <origin xyz="0.05 0.05 0" rpy="0 0 0"/>
        <axis xyz="0 0 1"/>
        <parent link="base_link"/>
        <child link="rotor_0"/>
    </joint>

    <link name="rotor_1">
        <visual>
            <origin xyz="0 0 0"/>
            <geometry><cylinder length="0.01" radius="0.045"/></geometry>
            <material name="gray"/>
        </visual>
        <inertial>
            <mass value="0.005"/>
            <inertia ixx="1e-6" ixy="0" ixz="0" iyy="1e-6" iyz="0" izz="2e-6"/>
        </inertial>
    </link>
    <joint name="rotor_1_joint" type="continuous">
        <origin xyz="0.05 -0.05 0" rpy="0 0 0"/>
        <axis xyz="0 0 -1"/> <parent link="base_link"/>
        <child link="rotor_1"/>
    </joint>

    <link name="rotor_2">
        <visual>
            <origin xyz="0 0 0"/>
            <geometry><cylinder length="0.01" radius="0.045"/></geometry>
            <material name="gray"/>
        </visual>
        <inertial>
            <mass value="0.005"/>
            <inertia ixx="1e-6" ixy="0" ixz="0" iyy="1e-6" iyz="0" izz="2e-6"/>
        </inertial>
    </link>
    <joint name="rotor_2_joint" type="continuous">
        <origin xyz="-0.05 0.05 0" rpy="0 0 0"/>
        <axis xyz="0 0 -1"/>
        <parent link="base_link"/>
        <child link="rotor_2"/>
    </joint>

    <link name="rotor_3">
        <visual>
            <origin xyz="0 0 0"/>
            <geometry><cylinder length="0.01" radius="0.045"/></geometry>
            <material name="gray"/>
        </visual>
        <inertial>
            <mass value="0.005"/>
            <inertia ixx="1e-6" ixy="0" ixz="0" iyy="1e-6" iyz="0" izz="2e-6"/>
        </inertial>
    </link>
    <joint name="rotor_3_joint" type="continuous">
        <origin xyz="-0.05 -0.05 0" rpy="0 0 0"/>
        <axis xyz="0 0 1"/>
        <parent link="base_link"/>
        <child link="rotor_3"/>
    </joint>

    <link name="camera_link">
        <visual>
            <origin xyz="0 0 0"/>
            <geometry><sphere radius="0.01"/></geometry>
            <material name="red"/>
        </visual>
        <collision>
            <geometry><sphere radius="0.01"/></geometry>
        </collision>
        <inertial>
            <mass value="1e-5"/>
            <inertia ixx="1e-6" ixy="0" ixz="0" iyy="1e-6" iyz="0" izz="1e-6"/>
        </inertial>
    </link>
    <joint name="camera_joint" type="fixed">
        <origin xyz="0.035 0 0" rpy="0 0 0"/>
        <parent link="base_link"/>
        <child link="camera_link"/>
    </joint>

</robot>
